log/output_500_2022_Attention_gpu3.log
wandb: Currently logged in as: pqy000 (pqythu). Use `wandb login --relogin` to force relogin
GPU device ID: 3
newdata/500_2022.npy
0
2024-09-07 11:35:16.933867: I tensorflow/core/platform/cpu_feature_guard.cc:193] This TensorFlow binary is optimized with oneAPI Deep Neural Network Library (oneDNN) to use the following CPU instructions in performance-critical operations:  AVX2 FMA
To enable them in other operations, rebuild TensorFlow with the appropriate compiler flags.
2024-09-07 11:35:17.888787: W tensorflow/compiler/xla/stream_executor/platform/default/dso_loader.cc:64] Could not load dynamic library 'libnvinfer.so.7'; dlerror: libnvinfer.so.7: cannot open shared object file: No such file or directory; LD_LIBRARY_PATH: /opt/cudnn/lib64:/usr/local/cuda/lib64
2024-09-07 11:35:17.888892: W tensorflow/compiler/xla/stream_executor/platform/default/dso_loader.cc:64] Could not load dynamic library 'libnvinfer_plugin.so.7'; dlerror: libnvinfer_plugin.so.7: cannot open shared object file: No such file or directory; LD_LIBRARY_PATH: /opt/cudnn/lib64:/usr/local/cuda/lib64
2024-09-07 11:35:17.888904: W tensorflow/compiler/tf2tensorrt/utils/py_utils.cc:38] TF-TRT Warning: Cannot dlopen some TensorRT libraries. If you would like to use Nvidia GPU with TensorRT, please make sure the missing libraries mentioned above are installed properly.
wandb: wandb version 0.17.9 is available!  To upgrade, please run:
wandb:  $ pip install wandb --upgrade
wandb: Tracking run with wandb version 0.12.17
wandb: Run data is saved locally in /home/qingyi/GPU20/DeepLOB/wandb/run-20240907_113513-3id1ppb8
wandb: Run `wandb offline` to turn off syncing.
wandb: Syncing run Attention
wandb: ⭐️ View project at https://wandb.ai/pqythu/futures500
wandb: 🚀 View run at https://wandb.ai/pqythu/futures500/runs/3id1ppb8
Model(
  (attn): MultiheadAttention(
    (out_proj): NonDynamicallyQuantizableLinear(in_features=10, out_features=10, bias=True)
  )
  (fc): Linear(in_features=10, out_features=5, bias=True)
)
number of parameters: 495
Training start
epoch  1 | time used:  0.94s | train_loss 1.519 | valid loss 1.525 | valid acc 0.344 | mae 1.866 | mse 6.131 | rmse 2.48 | r2 -1.32 | sharp 0.94
epoch  2 | time used:  0.16s | train_loss 1.510 | valid loss 1.465 | valid acc 0.344 | mae 1.866 | mse 6.131 | rmse 2.48 | r2 -1.32 | sharp 0.94
epoch  3 | time used:  0.16s | train_loss 1.508 | valid loss 1.465 | valid acc 0.344 | mae 1.866 | mse 6.131 | rmse 2.48 | r2 -1.32 | sharp 0.94
epoch  4 | time used:  0.17s | train_loss 1.504 | valid loss 1.465 | valid acc 0.344 | mae 1.866 | mse 6.131 | rmse 2.48 | r2 -1.32 | sharp 0.94
epoch  5 | time used:  0.20s | train_loss 1.518 | valid loss 1.546 | valid acc 0.280 | mae 2.134 | mse 7.201 | rmse 2.68 | r2 -1.72 | sharp 0.00
epoch  6 | time used:  0.17s | train_loss 1.521 | valid loss 1.546 | valid acc 0.280 | mae 2.134 | mse 7.201 | rmse 2.68 | r2 -1.72 | sharp 0.00
epoch  7 | time used:  0.20s | train_loss 1.516 | valid loss 1.465 | valid acc 0.344 | mae 1.866 | mse 6.131 | rmse 2.48 | r2 -1.32 | sharp 0.94
epoch  8 | time used:  0.22s | train_loss 1.494 | valid loss 1.446 | valid acc 0.344 | mae 1.866 | mse 6.131 | rmse 2.48 | r2 -1.32 | sharp 0.94
epoch  9 | time used:  0.17s | train_loss 1.509 | valid loss 1.465 | valid acc 0.344 | mae 1.866 | mse 6.131 | rmse 2.48 | r2 -1.32 | sharp 0.94
epoch 10 | time used:  0.24s | train_loss 1.496 | valid loss 1.539 | valid acc 0.280 | mae 2.134 | mse 7.201 | rmse 2.68 | r2 -1.72 | sharp 0.00
saving the model to ./save/2022_500/Attention/checkpoint10.pt
epoch 11 | time used:  0.22s | train_loss 1.645 | valid loss 1.546 | valid acc 0.280 | mae 2.134 | mse 7.201 | rmse 2.68 | r2 -1.72 | sharp 0.00
epoch 12 | time used:  0.18s | train_loss 1.514 | valid loss 1.546 | valid acc 0.280 | mae 2.134 | mse 7.201 | rmse 2.68 | r2 -1.72 | sharp 0.00
epoch 13 | time used:  0.19s | train_loss 1.517 | valid loss 1.546 | valid acc 0.280 | mae 2.134 | mse 7.201 | rmse 2.68 | r2 -1.72 | sharp 0.00
epoch 14 | time used:  0.20s | train_loss 1.613 | valid loss 1.829 | valid acc 0.089 | mae 1.554 | mse 3.399 | rmse 1.84 | r2 -0.28 | sharp 0.94
epoch 15 | time used:  0.24s | train_loss 1.820 | valid loss 1.827 | valid acc 0.089 | mae 1.554 | mse 3.399 | rmse 1.84 | r2 -0.28 | sharp 0.94
epoch 16 | time used:  0.24s | train_loss 1.820 | valid loss 1.717 | valid acc 0.083 | mae 1.694 | mse 3.934 | rmse 1.98 | r2 -0.49 | sharp 0.94
epoch 17 | time used:  0.30s | train_loss 1.550 | valid loss 1.465 | valid acc 0.344 | mae 1.866 | mse 6.131 | rmse 2.48 | r2 -1.32 | sharp 0.94
epoch 18 | time used:  0.19s | train_loss 1.508 | valid loss 1.465 | valid acc 0.344 | mae 1.866 | mse 6.131 | rmse 2.48 | r2 -1.32 | sharp 0.94
epoch 19 | time used:  0.15s | train_loss 1.505 | valid loss 1.465 | valid acc 0.344 | mae 1.866 | mse 6.131 | rmse 2.48 | r2 -1.32 | sharp 0.94
epoch 20 | time used:  0.20s | train_loss 1.510 | valid loss 1.465 | valid acc 0.344 | mae 1.866 | mse 6.131 | rmse 2.48 | r2 -1.32 | sharp 0.94
saving the model to ./save/2022_500/Attention/checkpoint20.pt
epoch 21 | time used:  0.20s | train_loss 1.509 | valid loss 1.465 | valid acc 0.344 | mae 1.866 | mse 6.131 | rmse 2.48 | r2 -1.32 | sharp 0.94
epoch 22 | time used:  0.18s | train_loss 1.508 | valid loss 1.465 | valid acc 0.344 | mae 1.866 | mse 6.131 | rmse 2.48 | r2 -1.32 | sharp 0.94
epoch 23 | time used:  0.18s | train_loss 1.508 | valid loss 1.465 | valid acc 0.344 | mae 1.866 | mse 6.131 | rmse 2.48 | r2 -1.32 | sharp 0.94
epoch 24 | time used:  0.19s | train_loss 1.506 | valid loss 1.465 | valid acc 0.344 | mae 1.866 | mse 6.131 | rmse 2.48 | r2 -1.32 | sharp 0.94
epoch 25 | time used:  0.20s | train_loss 1.507 | valid loss 1.465 | valid acc 0.344 | mae 1.866 | mse 6.131 | rmse 2.48 | r2 -1.32 | sharp 0.94
epoch 26 | time used:  0.18s | train_loss 1.505 | valid loss 1.465 | valid acc 0.344 | mae 1.866 | mse 6.131 | rmse 2.48 | r2 -1.32 | sharp 0.94
epoch 27 | time used:  0.18s | train_loss 1.503 | valid loss 1.465 | valid acc 0.344 | mae 1.866 | mse 6.131 | rmse 2.48 | r2 -1.32 | sharp 0.94
epoch 28 | time used:  0.18s | train_loss 1.509 | valid loss 1.465 | valid acc 0.344 | mae 1.866 | mse 6.131 | rmse 2.48 | r2 -1.32 | sharp 0.94
epoch 29 | time used:  0.18s | train_loss 1.505 | valid loss 1.465 | valid acc 0.344 | mae 1.866 | mse 6.131 | rmse 2.48 | r2 -1.32 | sharp 0.94
epoch 30 | time used:  0.17s | train_loss 1.510 | valid loss 1.465 | valid acc 0.344 | mae 1.866 | mse 6.131 | rmse 2.48 | r2 -1.32 | sharp 0.94
saving the model to ./save/2022_500/Attention/checkpoint30.pt
epoch 31 | time used:  0.16s | train_loss 1.504 | valid loss 1.465 | valid acc 0.344 | mae 1.866 | mse 6.131 | rmse 2.48 | r2 -1.32 | sharp 0.94
epoch 32 | time used:  0.17s | train_loss 1.506 | valid loss 1.465 | valid acc 0.344 | mae 1.866 | mse 6.131 | rmse 2.48 | r2 -1.32 | sharp 0.94
epoch 33 | time used:  0.17s | train_loss 1.505 | valid loss 1.465 | valid acc 0.344 | mae 1.866 | mse 6.131 | rmse 2.48 | r2 -1.32 | sharp 0.94
epoch 34 | time used:  0.15s | train_loss 1.505 | valid loss 1.465 | valid acc 0.344 | mae 1.866 | mse 6.131 | rmse 2.48 | r2 -1.32 | sharp 0.94
epoch 35 | time used:  0.17s | train_loss 1.506 | valid loss 1.465 | valid acc 0.344 | mae 1.866 | mse 6.131 | rmse 2.48 | r2 -1.32 | sharp 0.94
epoch 36 | time used:  0.15s | train_loss 1.504 | valid loss 1.465 | valid acc 0.344 | mae 1.866 | mse 6.131 | rmse 2.48 | r2 -1.32 | sharp 0.94
epoch 37 | time used:  0.17s | train_loss 1.507 | valid loss 1.465 | valid acc 0.344 | mae 1.866 | mse 6.131 | rmse 2.48 | r2 -1.32 | sharp 0.94
epoch 38 | time used:  0.19s | train_loss 1.511 | valid loss 1.465 | valid acc 0.344 | mae 1.866 | mse 6.131 | rmse 2.48 | r2 -1.32 | sharp 0.94
epoch 39 | time used:  0.18s | train_loss 1.511 | valid loss 1.546 | valid acc 0.280 | mae 2.134 | mse 7.201 | rmse 2.68 | r2 -1.72 | sharp 0.00
epoch 40 | time used:  0.17s | train_loss 1.512 | valid loss 1.546 | valid acc 0.280 | mae 2.134 | mse 7.201 | rmse 2.68 | r2 -1.72 | sharp 0.00
