log/output_500_2022_FuturesNet_gpu2.log
wandb: Currently logged in as: pqy000 (pqythu). Use `wandb login --relogin` to force relogin
GPU device ID: 2
newdata/500_2022.npy
0
2024-09-07 16:10:30.398323: I tensorflow/core/platform/cpu_feature_guard.cc:193] This TensorFlow binary is optimized with oneAPI Deep Neural Network Library (oneDNN) to use the following CPU instructions in performance-critical operations:  AVX2 FMA
To enable them in other operations, rebuild TensorFlow with the appropriate compiler flags.
2024-09-07 16:10:31.290645: W tensorflow/compiler/xla/stream_executor/platform/default/dso_loader.cc:64] Could not load dynamic library 'libnvinfer.so.7'; dlerror: libnvinfer.so.7: cannot open shared object file: No such file or directory; LD_LIBRARY_PATH: /opt/cudnn/lib64:/usr/local/cuda/lib64
2024-09-07 16:10:31.290740: W tensorflow/compiler/xla/stream_executor/platform/default/dso_loader.cc:64] Could not load dynamic library 'libnvinfer_plugin.so.7'; dlerror: libnvinfer_plugin.so.7: cannot open shared object file: No such file or directory; LD_LIBRARY_PATH: /opt/cudnn/lib64:/usr/local/cuda/lib64
2024-09-07 16:10:31.290752: W tensorflow/compiler/tf2tensorrt/utils/py_utils.cc:38] TF-TRT Warning: Cannot dlopen some TensorRT libraries. If you would like to use Nvidia GPU with TensorRT, please make sure the missing libraries mentioned above are installed properly.
wandb: wandb version 0.17.9 is available!  To upgrade, please run:
wandb:  $ pip install wandb --upgrade
wandb: Tracking run with wandb version 0.12.17
wandb: Run data is saved locally in /home/qingyi/GPU20/DeepLOB/wandb/run-20240907_161027-2yddnrbv
wandb: Run `wandb offline` to turn off syncing.
wandb: Syncing run FuturesNet
wandb: ⭐️ View project at https://wandb.ai/pqythu/futures500
wandb: 🚀 View run at https://wandb.ai/pqythu/futures500/runs/2yddnrbv
Model(
  (feature_extractor): InceptionTime(
    (network): Sequential(
      (0): InceptionBlock(
        (bottleneck): Conv1d(10, 32, kernel_size=(1,), stride=(1,))
        (conv1): Conv1d(32, 32, kernel_size=(9,), stride=(1,), padding=(4,))
        (conv2): Conv1d(32, 32, kernel_size=(19,), stride=(1,), padding=(9,))
        (conv3): Conv1d(32, 32, kernel_size=(39,), stride=(1,), padding=(19,))
        (pool): MaxPool1d(kernel_size=3, stride=1, padding=1, dilation=1, ceil_mode=False)
        (conv4): Conv1d(10, 32, kernel_size=(1,), stride=(1,))
        (bn): BatchNorm1d(128, eps=1e-05, momentum=0.1, affine=True, track_running_stats=True)
      )
      (1): InceptionBlock(
        (bottleneck): Conv1d(128, 32, kernel_size=(1,), stride=(1,))
        (conv1): Conv1d(32, 32, kernel_size=(9,), stride=(1,), padding=(4,))
        (conv2): Conv1d(32, 32, kernel_size=(19,), stride=(1,), padding=(9,))
        (conv3): Conv1d(32, 32, kernel_size=(39,), stride=(1,), padding=(19,))
        (pool): MaxPool1d(kernel_size=3, stride=1, padding=1, dilation=1, ceil_mode=False)
        (conv4): Conv1d(128, 32, kernel_size=(1,), stride=(1,))
        (bn): BatchNorm1d(128, eps=1e-05, momentum=0.1, affine=True, track_running_stats=True)
      )
      (2): InceptionBlock(
        (bottleneck): Conv1d(128, 32, kernel_size=(1,), stride=(1,))
        (conv1): Conv1d(32, 32, kernel_size=(9,), stride=(1,), padding=(4,))
        (conv2): Conv1d(32, 32, kernel_size=(19,), stride=(1,), padding=(9,))
        (conv3): Conv1d(32, 32, kernel_size=(39,), stride=(1,), padding=(19,))
        (pool): MaxPool1d(kernel_size=3, stride=1, padding=1, dilation=1, ceil_mode=False)
        (conv4): Conv1d(128, 32, kernel_size=(1,), stride=(1,))
        (bn): BatchNorm1d(128, eps=1e-05, momentum=0.1, affine=True, track_running_stats=True)
      )
      (3): InceptionBlock(
        (bottleneck): Conv1d(128, 32, kernel_size=(1,), stride=(1,))
        (conv1): Conv1d(32, 32, kernel_size=(9,), stride=(1,), padding=(4,))
        (conv2): Conv1d(32, 32, kernel_size=(19,), stride=(1,), padding=(9,))
        (conv3): Conv1d(32, 32, kernel_size=(39,), stride=(1,), padding=(19,))
        (pool): MaxPool1d(kernel_size=3, stride=1, padding=1, dilation=1, ceil_mode=False)
        (conv4): Conv1d(128, 32, kernel_size=(1,), stride=(1,))
        (bn): BatchNorm1d(128, eps=1e-05, momentum=0.1, affine=True, track_running_stats=True)
      )
      (4): InceptionBlock(
        (bottleneck): Conv1d(128, 32, kernel_size=(1,), stride=(1,))
        (conv1): Conv1d(32, 32, kernel_size=(9,), stride=(1,), padding=(4,))
        (conv2): Conv1d(32, 32, kernel_size=(19,), stride=(1,), padding=(9,))
        (conv3): Conv1d(32, 32, kernel_size=(39,), stride=(1,), padding=(19,))
        (pool): MaxPool1d(kernel_size=3, stride=1, padding=1, dilation=1, ceil_mode=False)
        (conv4): Conv1d(128, 32, kernel_size=(1,), stride=(1,))
        (bn): BatchNorm1d(128, eps=1e-05, momentum=0.1, affine=True, track_running_stats=True)
      )
      (5): InceptionBlock(
        (bottleneck): Conv1d(128, 32, kernel_size=(1,), stride=(1,))
        (conv1): Conv1d(32, 32, kernel_size=(9,), stride=(1,), padding=(4,))
        (conv2): Conv1d(32, 32, kernel_size=(19,), stride=(1,), padding=(9,))
        (conv3): Conv1d(32, 32, kernel_size=(39,), stride=(1,), padding=(19,))
        (pool): MaxPool1d(kernel_size=3, stride=1, padding=1, dilation=1, ceil_mode=False)
        (conv4): Conv1d(128, 32, kernel_size=(1,), stride=(1,))
        (bn): BatchNorm1d(128, eps=1e-05, momentum=0.1, affine=True, track_running_stats=True)
      )
    )
    (global_avg_pool): AdaptiveAvgPool1d(output_size=1)
  )
  (lstm): LSTM(8, 64, batch_first=True)
  (skip_connection): Linear(in_features=8, out_features=64, bias=True)
  (fc): Linear(in_features=64, out_features=5, bias=True)
)
number of parameters: 475589
Training start
epoch  1 | time used:  1.53s | train_loss 1.430 | valid loss 1.599 | valid acc 0.295 | mae 1.910 | mse 5.960 | rmse 2.44 | r2 -1.58 | sharp 0.00
epoch  2 | time used:  0.35s | train_loss 1.408 | valid loss 1.599 | valid acc 0.295 | mae 1.910 | mse 5.960 | rmse 2.44 | r2 -1.58 | sharp 0.00
epoch  3 | time used:  0.38s | train_loss 1.417 | valid loss 1.453 | valid acc 0.230 | mae 2.090 | mse 6.680 | rmse 2.58 | r2 -1.89 | sharp 3.85
epoch  4 | time used:  0.39s | train_loss 1.355 | valid loss 1.576 | valid acc 0.295 | mae 1.910 | mse 5.960 | rmse 2.44 | r2 -1.58 | sharp 0.00
epoch  5 | time used:  0.39s | train_loss 1.363 | valid loss 1.453 | valid acc 0.230 | mae 2.090 | mse 6.680 | rmse 2.58 | r2 -1.89 | sharp 3.85
epoch  6 | time used:  0.39s | train_loss 1.368 | valid loss 1.453 | valid acc 0.230 | mae 2.090 | mse 6.680 | rmse 2.58 | r2 -1.89 | sharp 3.85
epoch  7 | time used:  0.39s | train_loss 1.379 | valid loss 1.599 | valid acc 0.295 | mae 1.910 | mse 5.960 | rmse 2.44 | r2 -1.58 | sharp 0.00
epoch  8 | time used:  0.40s | train_loss 1.389 | valid loss 1.599 | valid acc 0.295 | mae 1.910 | mse 5.960 | rmse 2.44 | r2 -1.58 | sharp 0.00
epoch  9 | time used:  0.39s | train_loss 1.375 | valid loss 1.598 | valid acc 0.295 | mae 1.910 | mse 5.960 | rmse 2.44 | r2 -1.58 | sharp 0.00
epoch 10 | time used:  0.40s | train_loss 1.346 | valid loss 1.453 | valid acc 0.230 | mae 2.090 | mse 6.680 | rmse 2.58 | r2 -1.89 | sharp 3.85
saving the model to ./save/2022_500/FuturesNet/checkpoint10.pt
epoch 11 | time used:  0.40s | train_loss 1.371 | valid loss 1.453 | valid acc 0.230 | mae 2.090 | mse 6.680 | rmse 2.58 | r2 -1.89 | sharp 3.85
epoch 12 | time used:  0.39s | train_loss 1.390 | valid loss 1.455 | valid acc 0.230 | mae 2.090 | mse 6.680 | rmse 2.58 | r2 -1.89 | sharp 3.85
epoch 13 | time used:  0.39s | train_loss 1.392 | valid loss 1.453 | valid acc 0.230 | mae 2.090 | mse 6.680 | rmse 2.58 | r2 -1.89 | sharp 3.85
epoch 14 | time used:  0.39s | train_loss 1.403 | valid loss 1.599 | valid acc 0.295 | mae 1.910 | mse 5.960 | rmse 2.44 | r2 -1.58 | sharp 0.00
epoch 15 | time used:  0.39s | train_loss 1.412 | valid loss 1.599 | valid acc 0.295 | mae 1.910 | mse 5.960 | rmse 2.44 | r2 -1.58 | sharp 0.00
